[{"name": "test.test_notes.NoteTest.test_adding", "status": "failed", "message": "1 != 0 : 11. note after cleanup is present: Response should not contain 'NPYumQMKNZ'", "passed": false, "points": ["1.6.1", "1.6.2", "1.6.3", "1.6.4", "1.6.5"], "backtrace": ["  File \"/usr/lib/python3.8/unittest/case.py\", line 60, in testPartExecutor\n    yield\n", "  File \"/usr/lib/python3.8/unittest/case.py\", line 676, in run\n    self._callTestMethod(testMethod)\n", "  File \"/usr/lib/python3.8/unittest/case.py\", line 633, in _callTestMethod\n    method()\n", "  File \"/home/pc/Documents/cybersecurity/mooc-securing-software-23/part1-06.notebook/test/test_notes.py\", line 40, in test_adding\n    self.assertNotContains(response, items[i], msg_prefix='%d. note after cleanup is present' % (i + 1))\n", "  File \"/usr/local/lib/python3.8/dist-packages/django/test/testcases.py\", line 676, in assertNotContains\n    self.assertEqual(\n", "  File \"/usr/lib/python3.8/unittest/case.py\", line 912, in assertEqual\n    assertion_func(first, second, msg=msg)\n", "  File \"/usr/lib/python3.8/unittest/case.py\", line 905, in _baseAssertEqual\n    raise self.failureException(msg)\n"]}]